# 取消和超时

(原文档修改于 Last modified: 27 June 2022)

本节介绍协程取消和超时。

# 取消协程执行

在长时间运行的应用程序中，您可能需要对后台协程进行细粒度控制。例如，用户可能关闭了启动协程的页面，现在不再需要其结果，可以取消其操作。 launch 函数返回一个 Job，可用于取消正在运行的协程：

```kotlin
import kotlinx.coroutines.*

fun main() = runBlocking {
    val job = launch {
        repeat(1000) { i ->
            println("job: I'm sleeping $i ...")
            delay(500L)
        }
    }
    delay(1300L) // delay a bit
    println("main: I'm tired of waiting!")
    job.cancel() // cancels the job
    job.join() // waits for job's completion 
    println("main: Now I can quit.")    
}
```

它产生以下输出：

```text
job: I'm sleeping 0 ...
job: I'm sleeping 1 ...
job: I'm sleeping 2 ...
main: I'm tired of waiting!
main: Now I can quit.
```

一旦 main 调用 `job.cancel`，我们就看不到其他协程的任何输出，因为它已被取消。还有一个作业扩展函数 `cancelAndJoin` 结合了 `cancel` 和 `join` 调用。

#  取消是协作式的

协程取消是协作式的。协程代码必须协作才能取消。`kotlinx.coroutines` 中的所有挂起函数都是可取消的。他们检查协同程序的取消并在取消时抛出 [CancellationException](https://kotlinlang.org/api/kotlinx.coroutines/kotlinx-coroutines-core/kotlinx.coroutines/-cancellation-exception/index.html)。但是，如果协程正在计算中并且不检查是否取消，则无法取消，如以下示例所示：

```kotlin
import kotlinx.coroutines.*

fun main() = runBlocking {
    val startTime = System.currentTimeMillis()
    val job = launch(Dispatchers.Default) {
        var nextPrintTime = startTime
        var i = 0
        while (i < 5) { // computation loop, just wastes CPU
            // print a message twice a second
            if (System.currentTimeMillis() >= nextPrintTime) {
                println("job: I'm sleeping ${i++} ...")
                nextPrintTime += 500L
            }
        }
    }
    delay(1300L) // delay a bit
    println("main: I'm tired of waiting!")
    job.cancelAndJoin() // cancels the job and waits for its completion
    println("main: Now I can quit.")    
}
```

运行它可以看到即使在取消后它也会继续打印“I'm sleeping”，直到作业在五次迭代后自行完成。

通过捕获 CancellationException 而不是重新抛出它可以观察到相同的问题：
```kotlin
import kotlinx.coroutines.*

fun main() = runBlocking {
    val job = launch(Dispatchers.Default) {
        repeat(5) { i ->
            try {
                // print a message twice a second
                println("job: I'm sleeping $i ...")
                delay(500)
            } catch (e: Exception) {
                // log the exception
                println(e)
            }
        }
    }
    delay(1300L) // delay a bit
    println("main: I'm tired of waiting!")
    job.cancelAndJoin() // cancels the job and waits for its completion
    println("main: Now I can quit.")    
}
```

虽然捕获异常是一种 anti-pattern 反模式，但这个问题可能会以更微妙的方式出现，例如在使用 [runCatching](https://kotlinlang.org/api/latest/jvm/stdlib/kotlin/run-catching.html) 函数时，它不会重新抛出 CancellationException。

# 使计算代码可取消

有两种方法可以使计算代码可取消。第一个是定期调用检查取消的挂起函数。有一个 `yield` 函数是一个很好的选择。另一种是显式检查取消状态。让我们试试后一种方法。

将前面示例中的 `while (i < 5)` 替换为 `while (isActive)` 并重新运行它。

```kotlin
import kotlinx.coroutines.*

fun main() = runBlocking {
    val startTime = System.currentTimeMillis()
    val job = launch(Dispatchers.Default) {
        var nextPrintTime = startTime
        var i = 0
        while (isActive) { // cancellable computation loop
            // print a message twice a second
            if (System.currentTimeMillis() >= nextPrintTime) {
                println("job: I'm sleeping ${i++} ...")
                nextPrintTime += 500L
            }
        }
    }
    delay(1300L) // delay a bit
    println("main: I'm tired of waiting!")
    job.cancelAndJoin() // cancels the job and waits for its completion
    println("main: Now I can quit.")    
}
```

如您所见，现在这个循环被取消了。 `isActive` 是通过 [CoroutineScope](https://kotlinlang.org/api/kotlinx.coroutines/kotlinx-coroutines-core/kotlinx.coroutines/-coroutine-scope/index.html) 对象在协程内部可用的扩展属性。

# 使用 finally 关闭资源

可取消的挂起函数在取消时抛出 CancellationException，可以用通常的方式处理。例如，`try {...} finally {...} ` 表达式和 Kotlin 的 `use` 函数在协程被取消时正常执行它们的终结操作：

```kotlin
import kotlinx.coroutines.*

fun main() = runBlocking {
    val job = launch {
        try {
            repeat(1000) { i ->
                println("job: I'm sleeping $i ...")
                delay(500L)
            }
        } finally {
            println("job: I'm running finally")
        }
    }
    delay(1300L) // delay a bit
    println("main: I'm tired of waiting!")
    job.cancelAndJoin() // cancels the job and waits for its completion
    println("main: Now I can quit.")    
}
```

`join` 和 `cancelAndJoin` 都等待所有完成操作完成，因此上面的示例产生以下输出：

```text
job: I'm sleeping 0 ...
job: I'm sleeping 1 ...
job: I'm sleeping 2 ...
main: I'm tired of waiting!
job: I'm running finally
main: Now I can quit.
```

# 运行不可取消的代码块

任何在上一个示例的 `finally` 块中使用挂起函数的尝试都会导致 CancellationException，因为运行此代码的协程已被取消。通常，这不是问题，因为所有行为良好的关闭操作（关闭文件、取消作业或关闭任何类型的通信通道）通常都是非阻塞的，并且不涉及任何挂起函数。但是，在极少数情况下，当您需要在已取消的协程中暂停时，您可以使用 `withContext(NonCancellable) {...}` 函数和 `NonCancellable` 上下文将相应的代码包装在 `withContext(NonCancellable) {...}` 中，如下例所示：

```kotlin
import kotlinx.coroutines.*

fun main() = runBlocking {
    val job = launch {
        try {
            repeat(1000) { i ->
                println("job: I'm sleeping $i ...")
                delay(500L)
            }
        } finally {
            withContext(NonCancellable) {
                println("job: I'm running finally")
                delay(1000L)
                println("job: And I've just delayed for 1 sec because I'm non-cancellable")
            }
        }
    }
    delay(1300L) // delay a bit
    println("main: I'm tired of waiting!")
    job.cancelAndJoin() // cancels the job and waits for its completion
    println("main: Now I can quit.")    
}
```

# 超时

取消协程执行的最明显的实际原因是因为它的执行时间超过了某个超时时间。虽然您可以手动跟踪对相应作业的引用并启动一个单独的协程以在延迟后取消跟踪的协程，但有一个随时可用的 [withTimeout](https://kotlinlang.org/api/kotlinx.coroutines/kotlinx-coroutines-core/kotlinx.coroutines/with-timeout.html) 函数可以执行此操作。看下面的例子：

```kotlin
import kotlinx.coroutines.*

fun main() = runBlocking {
    withTimeout(1300L) {
        repeat(1000) { i ->
            println("I'm sleeping $i ...")
            delay(500L)
        }
    }
}
```

它产生以下输出：

```text
I'm sleeping 0 ...
I'm sleeping 1 ...
I'm sleeping 2 ...
Exception in thread "main" kotlinx.coroutines.TimeoutCancellationException: Timed out waiting for 1300 ms
```

withTimeout 抛出的 `TimeoutCancellationException` 是CancellationException的子类。我们之前没有在控制台上看到它的堆栈跟踪。这是因为在取消的协程中，CancellationException 被认为是协程完成的正常原因。然而，在这个例子中，我们在 main 函数中使用了 `withTimeout`。

由于取消只是一个 exception ，所有资源都以通常的方式关闭。如果您需要专门针对任何类型的超时执行一些额外的操作，可以将超时的代码 通过 `try {...} catch (e: TimeoutCancellationException) {...}` 代码块进行包裹 或者使用类似于 `withTimeout` 但在超时时返回 null 而不是抛出异常的 [withTimeoutOrNull](https://kotlinlang.org/api/kotlinx.coroutines/kotlinx-coroutines-core/kotlinx.coroutines/with-timeout-or-null.html) 函数：

```kotlin
import kotlinx.coroutines.*

fun main() = runBlocking {
    val result = withTimeoutOrNull(1300L) {
        repeat(1000) { i ->
            println("I'm sleeping $i ...")
            delay(500L)
        }
        "Done" // will get cancelled before it produces this result
    }
    println("Result is $result")
}
```

运行此代码时不再出现异常：

```text
I'm sleeping 0 ...
I'm sleeping 1 ...
I'm sleeping 2 ...
Result is null
```

# 异步超时和资源

withTimeout 中的超时事件相对于在其块中运行的代码是异步的，并且可能随时发生，甚至就在从超时块内部返回之前。如果您在块内打开或获取某些需要在块外关闭或释放的资源，请记住这一点。

例如，这里我们使用 `Resource` 类模拟一个可关闭的资源，它通过增加获取的计数器并从其 `close` 函数中减少该计数器来简单地跟踪它被创建的次数。让我们运行许多具有小超时的协程，尝试在延迟一段时间后从 `withTimeout` 块内部获取此资源，然后从外部释放它。

```kotlin
import kotlinx.coroutines.*

var acquired = 0

class Resource {
    init { acquired++ } // Acquire the resource
    fun close() { acquired-- } // Release the resource
}

fun main() {
    runBlocking {
        repeat(100_000) { // Launch 100K coroutines
            launch { 
                val resource = withTimeout(60) { // Timeout of 60 ms
                    delay(50) // Delay for 50 ms
                    Resource() // Acquire a resource and return it from withTimeout block     
                }
                resource.close() // Release the resource
            }
        }
    }
    // Outside of runBlocking all coroutines have completed
    println(acquired) // Print the number of resources still acquired
}
```
如果您运行上面的代码，您会发现它并不总是打印零，尽管它可能取决于您机器的计时，您可能需要在此示例中调整超时以实际看到非零值。

> 请注意，这里从 100K 协程递增和递减获取的计数器是完全安全的，因为它总是发生在同一个主线程中。更多相关内容将在有关协程上下文的章节中进行解释。

要解决此问题，您可以在变量中存储对资源的引用，而不是从 `withTimeout` 块中返回它。

```kotlin
 import kotlinx.coroutines.*

var acquired = 0

class Resource {
    init { acquired++ } // Acquire the resource
    fun close() { acquired-- } // Release the resource
}

fun main() {
    runBlocking {
        repeat(100_000) { // Launch 100K coroutines
            launch { 
                var resource: Resource? = null // Not acquired yet
                try {
                    withTimeout(60) { // Timeout of 60 ms
                        delay(50) // Delay for 50 ms
                        resource = Resource() // Store a resource to the variable if acquired      
                    }
                    // We can do something else with the resource here
                } finally {  
                    resource?.close() // Release the resource if it was acquired
                }
            }
        }
    }
    // Outside of runBlocking all coroutines have completed
    println(acquired) // Print the number of resources still acquired
}
```

此示例始终打印零。资源不泄漏。
