# 协程异常处理

(原文档 Last modified: 27 June 2022)

本节介绍异常处理和异常取消。我们已经知道取消的协程会在挂起点抛出 CancellationException 并且它会被协程的机制忽略。这里我们看看如果在取消过程中抛出异常或者同一个协程的多个子协程抛出异常会发生什么。

# 异常传播

协程构建器有两种形式：自动传播异常（ launch 和 actor ）或将它们暴露给用户（ async 和 produce ）。当这些构建器用于创建一个根协程时，它不是另一个协程的子级，前者将异常视为未捕获的异常，类似于 Java 的 `Thread.uncaughtExceptionHandler`，而后者依赖于用户来消费最终的异常，例如通过 `await` 或 `receive`（ produce 和 receive 在 [Channels]() 部分介绍）。

可以通过使用 GlobalScope 创建根协程的简单示例来演示：

> GlobalScope 是一个微妙的 API，使用不当可能会以不寻常的方式适得其反。为整个应用程序创建根协程是 `GlobalScope` 罕见的合法用途之一，因此您必须通过 `@OptIn(DelicateCoroutinesApi::class)` 明确选择加入使用 `GlobalScope`。

```kotlin
import kotlinx.coroutines.*

@OptIn(DelicateCoroutinesApi::class)
fun main() = runBlocking {
    val job = GlobalScope.launch { // root coroutine with launch
        println("Throwing exception from launch")
        throw IndexOutOfBoundsException() // Will be printed to the console by Thread.defaultUncaughtExceptionHandler
    }
    job.join()
    println("Joined failed job")
    val deferred = GlobalScope.async { // root coroutine with async
        println("Throwing exception from async")
        throw ArithmeticException() // Nothing is printed, relying on user to call await
    }
    try {
        deferred.await()
        println("Unreached")
    } catch (e: ArithmeticException) {
        println("Caught ArithmeticException")
    }
}
```

此代码的输出是（带调试）：

```text
Throwing exception from launch
Exception in thread "DefaultDispatcher-worker-2 @coroutine#2" java.lang.IndexOutOfBoundsException
Joined failed job
Throwing exception from async
Caught ArithmeticException
```

# CoroutineExceptionHandler

可以自定义将 **未捕获的** 异常打印到控制台的默认行为。根协程上的 [CoroutineExceptionHandler](https://kotlinlang.org/api/kotlinx.coroutines/kotlinx-coroutines-core/kotlinx.coroutines/-coroutine-exception-handler/index.html) 上下文元素可用作此根协程及其所有可能发生自定义异常处理的子级的通用 `catch` 块。它类似于 `Thread.uncaughtExceptionHandler`。您无法从 `CoroutineExceptionHandler` 中的异常中恢复。调用处理程序时，协程已经完成并出现相应的异常。通常，处理程序用于记录异常、显示某种错误消息、终止和/或重新启动应用程序。

`CoroutineExceptionHandler` 仅在 **未捕获的** 异常上调用——未以任何其他方式处理的异常。特别是，所有子协程（在另一个 Job 的上下文中创建的协程）将异常处理委托给它们的父协程，父协程也委托给它的父协程，依此类推直到根，因此安装在它们上下文中的 CoroutineExceptionHandler 永远不会被使用。除此之外，async builder 总是捕获所有异常并在生成的 Deferred 对象中表示它们，因此它的 CoroutineExceptionHandler 也没有效果。

> 在 supervision 作用域内运行的协程不会将异常传播到其父级，因此被排除在该规则之外。本文档的进一步[Supervision](#Supervision)部分提供了更多详细信息。

```kotlin
 import kotlinx.coroutines.*

@OptIn(DelicateCoroutinesApi::class)
fun main() = runBlocking {
    val handler = CoroutineExceptionHandler { _, exception -> 
        println("CoroutineExceptionHandler got $exception") 
    }
    val job = GlobalScope.launch(handler) { // root coroutine, running in GlobalScope
        throw AssertionError()
    }
    val deferred = GlobalScope.async(handler) { // also root, but async instead of launch
        throw ArithmeticException() // Nothing will be printed, relying on user to call deferred.await()
    }
    joinAll(job, deferred)    
}
```

此代码的输出是：

```text
CoroutineExceptionHandler got java.lang.AssertionError
```

# 取消和异常

取消与异常密切相关。协程在内部使用 `CancellationException` 来取消，这些异常会被所有处理程序忽略，因此它们应该只用作附加调试信息的来源，可以通过 `catch` 块获取。当使用 `Job.cancel` 取消协程时，它会终止，但不会取消其父级。

```kotlin
import kotlinx.coroutines.*

fun main() = runBlocking {
    val job = launch {
        val child = launch {
            try {
                delay(Long.MAX_VALUE)
            } finally {
                println("Child is cancelled")
            }
        }
        yield()
        println("Cancelling child")
        child.cancel()
        child.join()
        yield()
        println("Parent is not cancelled")
    }
    job.join()    
}
```

此代码的输出是：

```text
Cancelling child
Child is cancelled
Parent is not cancelled
```

如果协程遇到 CancellationException 以外的异常，它会取消带有该异常的父级。此行为不能被覆盖，用于为结构化并发提供稳定的协程层次结构。 `CoroutineExceptionHandler` 实现不用于子协程。

> 在这些示例中，CoroutineExceptionHandler 始终安装到在 GlobalScope 中创建的协程。将异常处理程序安装到在主 runBlocking 作用域内启动的协程是没有意义的，因为尽管安装了异常处理程序，但当其子程序异常完成时，主协程将始终被取消。

原始异常仅在其所有子项终止时由父项处理，如下例所示。

```kotlin
import kotlinx.coroutines.*

@OptIn(DelicateCoroutinesApi::class)
fun main() = runBlocking {
    val handler = CoroutineExceptionHandler { _, exception -> 
        println("CoroutineExceptionHandler got $exception") 
    }
    val job = GlobalScope.launch(handler) {
        launch { // the first child
            try {
                delay(Long.MAX_VALUE)
            } finally {
                withContext(NonCancellable) {
                    println("Children are cancelled, but exception is not handled until all children terminate")
                    delay(100)
                    println("The first child finished its non cancellable block")
                }
            }
        }
        launch { // the second child
            delay(10)
            println("Second child throws an exception")
            throw ArithmeticException()
        }
    }
    job.join() 
}
```

此代码的输出是：

```text
Second child throws an exception
Children are cancelled, but exception is not handled until all children terminate
The first child finished its non cancellable block
CoroutineExceptionHandler got java.lang.ArithmeticException
```

# 异常聚合

当协程的多个子协程因异常而失败时，一般规则是“第一个异常获胜”，因此第一个异常会得到处理。在第一个异常之后发生的所有其他异常都作为被抑制的异常附加到第一个异常。

```kotlin
import kotlinx.coroutines.*
import java.io.*

@OptIn(DelicateCoroutinesApi::class)
fun main() = runBlocking {
    val handler = CoroutineExceptionHandler { _, exception ->
        println("CoroutineExceptionHandler got $exception with suppressed ${exception.suppressed.contentToString()}")
    }
    val job = GlobalScope.launch(handler) {
        launch {
            try {
                delay(Long.MAX_VALUE) // it gets cancelled when another sibling fails with IOException
            } finally {
                throw ArithmeticException() // the second exception
            }
        }
        launch {
            delay(100)
            throw IOException() // the first exception
        }
        delay(Long.MAX_VALUE)
    }
    job.join()  
}
```

> 注意：以上代码只能在支持 `suppressed ` 异常的 JDK7+ 上正常工作

此代码的输出是：

```text
CoroutineExceptionHandler got java.io.IOException with suppressed [java.lang.ArithmeticException]
```

> 请注意，此机制目前仅适用于 Java 1.7+ 版本。 JS 和 Native 的限制是暂时的，以后会取消。

取消异常是透明的，默认情况下是 unwrapped ：

```kotlin
import kotlinx.coroutines.*
import java.io.*

@OptIn(DelicateCoroutinesApi::class)
fun main() = runBlocking {
    val handler = CoroutineExceptionHandler { _, exception ->
        println("CoroutineExceptionHandler got $exception")
    }
    val job = GlobalScope.launch(handler) {
        val inner = launch { // all this stack of coroutines will get cancelled
            launch {
                launch {
                    throw IOException() // the original exception
                }
            }
        }
        try {
            inner.join()
        } catch (e: CancellationException) {
            println("Rethrowing CancellationException with original cause")
            throw e // 重新抛出取消异常，但原始 IOException 到达处理程序  
        }
    }
    job.join()    
}
```

此代码的输出是：

```text
Rethrowing CancellationException with original cause
CoroutineExceptionHandler got java.io.IOException
```

# Supervision

正如我们之前研究过的，取消是一种在整个协程层次结构中传播的双向关系。让我们看一下需要单向取消的情况。

这种要求的一个很好的例子是在其作用域内定义了 job 的 UI 组件。如果 UI 的任何子任务失败，并不总是需要取消（有效地杀死）整个 UI 组件，但如果 UI 组件被销毁（并且它的作业被取消），则有必要取消所有子作业因为不再需要他们的结果。

另一个例子是一个服务器进程产生多个子 jobs 并且需要监督它们的执行，跟踪它们的失败并且只重新启动失败的。

## Supervision job

[SupervisorJob](https://kotlinlang.org/api/kotlinx.coroutines/kotlinx-coroutines-core/kotlinx.coroutines/-supervisor-job.html) 可用于这些目的。它类似于常规 Job with the only exception that cancellation is propagated only downwards (向下传播)。使用以下示例可以很容易地证明这一点：

```kotlin
import kotlinx.coroutines.*

fun main() = runBlocking {
    val supervisor = SupervisorJob()
    with(CoroutineScope(coroutineContext + supervisor)) {
        // launch the first child -- its exception is ignored for this example (don't do this in practice!)
        val firstChild = launch(CoroutineExceptionHandler { _, _ ->  }) {
            println("The first child is failing")
            throw AssertionError("The first child is cancelled")
        }
        // launch the second child
        val secondChild = launch {
            firstChild.join()
            // 第一个 child 的"取消"不会传播到第二个 child
            println("The first child is cancelled: ${firstChild.isCancelled}, but the second one is still active")
            try {
                delay(Long.MAX_VALUE)
            } finally {
                // 但是 supervisor 的 “取消” 是被传播的
                println("The second child is cancelled because the supervisor was cancelled")
            }
        }
        // wait until the first child fails & completes
        firstChild.join()
        println("Cancelling the supervisor")
        supervisor.cancel()
        secondChild.join()
    }
}
```

此代码的输出是：

```text
The first child is failing
The first child is cancelled: true, but the second one is still active
Cancelling the supervisor
The second child is cancelled because the supervisor was cancelled
```

## Supervision scope

我们可以使用 [supervisorScope](https://kotlinlang.org/api/kotlinx.coroutines/kotlinx-coroutines-core/kotlinx.coroutines/supervisor-scope.html) 代替 [coroutineScope](https://kotlinlang.org/api/kotlinx.coroutines/kotlinx-coroutines-core/kotlinx.coroutines/coroutine-scope.html) 来实现 _scoped_ 并发。它仅在一个方向上传播取消，并且仅当它自身失败时才取消其所有子项。它也像 `coroutineScope` 一样在完成之前等待所有 children。

```kotlin
import kotlin.coroutines.*
import kotlinx.coroutines.*

fun main() = runBlocking {
    try {
        supervisorScope {
            val child = launch {
                try {
                    println("The child is sleeping")
                    delay(Long.MAX_VALUE)
                } finally {
                    println("The child is cancelled")
                }
            }
            // Give our child a chance to execute and print using yield 
            yield()
            println("Throwing an exception from the scope")
            throw AssertionError()
        }
    } catch(e: AssertionError) {
        println("Caught an assertion error")
    }
}
```

此代码的输出是：

```text
The child is sleeping
Throwing an exception from the scope
The child is cancelled
Caught an assertion error
```

### supervised 协程中的异常

常规 jobs 和 supervisor jobs 之间的另一个重要区别是异常处理。每个 children 都应该通过异常处理机制自己处理它的异常。这种差异来自于子级的失败不会传播到父级这一事实。这意味着直接在 supervisorScope 内启动的协程确实使用安装在其作用域内的 CoroutineExceptionHandler，其方式与根协程相同（有关详细信息，请参阅 [CoroutineExceptionHandler](#CoroutineExceptionHandler) 部分）。

```kotlin
import kotlin.coroutines.*
import kotlinx.coroutines.*

fun main() = runBlocking {
    val handler = CoroutineExceptionHandler { _, exception -> 
        println("CoroutineExceptionHandler got $exception") 
    }
    supervisorScope {
        val child = launch(handler) {
            println("The child throws an exception")
            throw AssertionError()
        }
        println("The scope is completing")
    }
    println("The scope is completed")
}
```

此代码的输出是：

```text
The scope is completing
The child throws an exception
CoroutineExceptionHandler got java.lang.AssertionError
The scope is completed
```


